<mujoco model='rolling ball'>
	<compiler inertiafromgeom='true' angle='degree'/>
    <default>
        <joint limited='true' damping='1' armature='0'/>
        <geom contype='1' conaffinity='1' condim='1' rgba='0.5 0.3 .4 1'
        	margin="0.001" solref=".02 1" solimp=".8 .8 .01"/>
        <motor ctrlrange='-.4 .4' ctrllimited='true'/>
		<!-- add some classes -->
    </default>

    <option timestep='0.1' iterations="50" tolerance="1e-10" solver="Newton" jacobian="dense" cone="elliptic"/>

    <size nstack="1000000"/>

    <visual>
        <map fogstart="3" fogend="5" force="0.1" znear="0.5"/>
        <quality shadowsize="2048" offsamples="8"/>
        <global offwidth="800" offheight="800"/>
    </visual>

    <asset>
		<texture type="skybox" builtin="gradient" width="128" height="128" rgb1=".4 .6 .8"
            rgb2="0 0 0"/>
        <texture name="texgeom" type="cube" builtin="flat" mark="cross" width="127" height="1278"
            rgb1="0.4 0.4 0.1" rgb2="0.5 0.5 0.1" markrgb="1 1 1" random="0.01"/>
        <texture name="texplane" type="2d" builtin="checker" rgb1=".2 .3 .4" rgb2=".1 0.15 0.2"
            width="512" height="512"/>
        <material name='MatPlane' reflectance='0.3' texture="texplane" texrepeat="1 1" texuniform="true"/>
    </asset>

    <worldbody>
        <light mode='targetbodycom' target='ball' directional='false' castshadow='false'  diffuse='.8 .8 .8' specular='0.3 0.3 0.3' pos='1 1 4.0' dir='0 0 -1'/>

		<body name='ball' pos='0.3 0.3 0.0'>
			<joint name='slide1' type='slide' range='-1.0 1.0' axis='1 0 0' />
			<joint name='slide2' type='slide' range='-1.0 1.0' axis='0 1 0' />
			<geom name='ball' type='sphere' size="0.04" rgba=".5 .0 .5 1"/>
		</body>

		<geom name='target' type='sphere' pos='-0.3 -0.3 0.0' size='0.09' rgba=".5 .5 .0 1"/>


        <!-- obstacle -->
        <body name='obstacle' pos='0 0 0'>
		    <geom name = 'obstacle' type='sphere' rgba='1 1 1 1' size = '0.14'/>
        </body>

        <camera name="camera1" mode="targetbody" pos="0 0 4.0" />
    </worldbody>

    <actuator>
        <motor joint='slide1' name='slide1' ctrlrange='-1.0 1.0'/>
		<motor joint='slide2' name='slide2' ctrlrange='-1.0 1.0'/>
	</actuator>

</mujoco>
